Workbook

Sheet DASH
B1: 📦 Dashboard de Emissões
B2: ="Base: "&COUNTIF(DADOS!$G$2:$G$5001,"?*")&" CT-es • Período: "&IF(COUNT(DADOS!$A$2:$A$5001)=0,"—",TEXT(MIN(DADOS!$A$2:$A$5001),"dd/mm/yyyy")&" a "&TEXT(MAX(DADOS!$A$2:$A$5001),"dd/mm/yyyy"))&" • Filtrados: "&COUNTIF(DADOS!$V$2:$V$5001,TRUE)&" • "&IF(AND(BASE!$A$1="Modal",BASE!$H$1="DEST",BASE!$J$1="ID Conhec",BASE!$K$1="DATA",BASE!$L$1="DT. PREV. ENTREGA",BASE!$O$1="PRAZO",BASE!$S$1="TIPO FRETE",BASE!$V$1="VALOR DO FRETE",BASE!$W$1="VOL.",BASE!$X$1="REMETENTE",BASE!$Y$1="DESTINATARIO",BASE!$AA$1="NOTAS"),"✔ Layout da base reconhecido","⚠ Layout da BASE diferente do esperado — conferir colunas / colar a partir da A1")&IF(COUNTA(BASE!$J$5002:$J$6000)>0," • ⚠ Base passa de 5000 linhas: excedente ignorado","")&IF(COUNTIF(DADOS!$G$2:$G$5001,"?*")>COUNT(DADOS!$A$2:$A$5001)," • ⚠ "&(COUNTIF(DADOS!$G$2:$G$5001,"?*")-COUNT(DADOS!$A$2:$A$5001))&" linha(s) com data inválida","") -> Base: 953 CT-es • Período: 09/10/2026 a 10/10/2026 • Filtrados: 11 • ✔ Layout da base reconhecido
B3: Emissão de | C3: Emissão até | D3: Prazo de (dias) | E3: Prazo até | F3: Destino | G3: Remetente | H3: Situação CT-e | I3: Tipo frete | J3: Célula | K3: Categoria | L3: Buscar: ID / NF / AWB / destinatário
F4: Todos | G4: DATEN TECNOLOGIA | H4: AUTORIZADO | I4: Todos | J4: Todos | K4: Todos
B6: CT-es emitidos | D6: Volumes | F6: Valor de frete | H6: Frete médio / CT-e | J6: Prazo médio (dias) | L6: CT-e autorizado | N6: Pendências de CT-e
B7: =COUNTIF(DADOS!$V$2:$V$5001,TRUE) -> 11 | D7: =SUMIFS(DADOS!$Q$2:$Q$5001,DADOS!$V$2:$V$5001,TRUE) -> 16 | F7: =SUMIFS(DADOS!$P$2:$P$5001,DADOS!$V$2:$V$5001,TRUE) -> 1445.83 | H7: =IFERROR(SUMIFS(DADOS!$P$2:$P$5001,DADOS!$V$2:$V$5001,TRUE)/COUNTIF(DADOS!$V$2:$V$5001,TRUE),0) -> 131.43909 | J7: =IFERROR(AVERAGEIFS(DADOS!$C$2:$C$5001,DADOS!$V$2:$V$5001,TRUE),0) -> 9.8181818 | L7: =IFERROR(COUNTIFS(DADOS!$V$2:$V$5001,TRUE,DADOS!$L$2:$L$5001,"AUTORIZADO")/COUNTIF(DADOS!$V$2:$V$5001,TRUE),0) -> 1 | N7: =COUNTIFS(DADOS!$V$2:$V$5001,TRUE,DADOS!$L$2:$L$5001,"<>AUTORIZADO") -> 0
B8: ="de "&COUNTIF(DADOS!$G$2:$G$5001,"?*")&" na base" -> de 953 na base | D8: ="média "&IFERROR(ROUND(SUMIFS(DADOS!$Q$2:$Q$5001,DADOS!$V$2:$V$5001,TRUE)/COUNTIF(DADOS!$V$2:$V$5001,TRUE),1),0)&" por CT-e" -> média 1,5 por CT-e | F8: ="CIF: R$ "&ROUND(SUMIFS(DADOS!$P$2:$P$5001,DADOS!$V$2:$V$5001,TRUE,DADOS!$J$2:$J$5001,"CIF"),0) -> CIF: R$ 1446 | H8: ="maior: R$ "&IFERROR(ROUND(MAXIFS(DADOS!$P$2:$P$5001,DADOS!$V$2:$V$5001,TRUE),0),0) -> maior: R$ 192 | J8: ="mín "&IFERROR(MINIFS(DADOS!$C$2:$C$5001,DADOS!$V$2:$V$5001,TRUE),"-")&" • máx "&IFERROR(MAXIFS(DADOS!$C$2:$C$5001,DADOS!$V$2:$V$5001,TRUE),"-") -> mín 8 • máx 12 | L8: =COUNTIFS(DADOS!$V$2:$V$5001,TRUE,DADOS!$L$2:$L$5001,"AUTORIZADO")&" autorizados" -> 11 autorizados | N8: ="erro: "&COUNTIFS(DADOS!$V$2:$V$5001,TRUE,DADOS!$L$2:$L$5001,"ERRO")&" • sem CT-e: "&COUNTIFS(DADOS!$V$2:$V$5001,TRUE,DADOS!$L$2:$L$5001,"SEM CT-E") -> erro: 0 • sem CT-e: 0
B9: Gráficos (respondem aos filtros acima)
B66: Detalhamento (respeita os filtros — use a busca para localizar ID, NF ou AWB)
B67: =IFERROR(__xludf.DUMMYFUNCTION("IFERROR(QUERY(DADOS!$A$1:$V$5001,""select Col1, Col7, Col8, Col9, Col4, Col5, Col6, Col10, Col2, Col3, Col17, Col16, Col12, Col11 where Col22 = true order by Col1 desc, Col4, Col7 limit 2000 label Col1 'Emissão', Col7 'ID Conhec.', Col8 'NF', Col9 'AWB', "&"Col4 'Destino', Col5 'Destinatário', Col6 'Remetente', Col10 'Tipo frete', Col2 'Prev. entrega', Col3 'Prazo (dias)', Col17 'Vol.', Col16 'Frete (R$)', Col12 'CT-e', Col11 'Célula'"",1),""Nenhum registro para os filtros selecionados"")"),"Emissão") -> Emissão | C67: =IFERROR(__xludf.DUMMYFUNCTION("""COMPUTED_VALUE"""),"ID Conhec.") -> ID Conhec. | D67: =IFERROR(__xludf.DUMMYFUNCTION("""COMPUTED_VALUE"""),"NF") -> NF | E67: =IFERROR(__xludf.DUMMYFUNCTION("""COMPUTED_VALUE"""),"AWB") -> AWB | F67: =IFERROR(__xludf.DUMMYFUNCTION("""COMPUTED_VALUE"""),"Destino") -> Destino | G67: =IFERROR(__xludf.DUMMYFUNCTION("""COMPUTED_VALUE"""),"Destinatário") -> Destinatário | H67: =IFERROR(__xludf.DUMMYFUNCTION("""COMPUTED_VALUE"""),"Remetente") -> Remetente | I67: =IFERROR(__xludf.DUMMYFUNCTION("""COMPUTED_VALUE"""),"Tipo frete") -> Tipo frete | J67: =IFERROR(__xludf.DUMMYFUNCTION("""COMPUTED_VALUE"""),"Prev. entrega") -> Prev. entrega | K67: =IFERROR(__xludf.DUMMYFUNCTION("""COMPUTED_VALUE"""),"Prazo (dias)") -> Prazo (dias) | L67: =IFERROR(__xludf.DUMMYFUNCTION("""COMPUTED_VALUE"""),"Vol.") -> Vol. | M67: =IFERROR(__xludf.DUMMYFUNCTION("""COMPUTED_VALUE"""),"Frete (R$)") -> Frete (R$) | N67: =IFERROR(__xludf.DUMMYFUNCTION("""COMPUTED_VALUE"""),"CT-e") -> CT-e | O67: =IFERROR(__xludf.DUMMYFUNCTION("""COMPUTED_VALUE"""),"Célula") -> Célula
B68: =IFERROR(__xludf.DUMMYFUNCTION("""COMPUTED_VALUE"""),46304.0) -> 46304 | C68: =IFERROR(__xludf.DUMMYFUNCTION("""COMPUTED_VALUE"""),"266834276") -> 266834276 | D68: =IFERROR(__xludf.DUMMYFUNCTION("""COMPUTED_VALUE"""),"107264") -> 107264 | E68: =IFERROR(__xludf.DUMMYFUNCTION("""COMPUTED_VALUE"""),"8177626") -> 8177626 | F68: =IFERROR(__xludf.DUMMYFUNCTION("""COMPUTED_VALUE"""),"ABS") -> ABS | G68: =IFERROR(__xludf.DUMMYFUNCTION("""COMPUTED_VALUE"""),"SAGARA INFORMATICA LTDA") -> SAGARA INFORMATICA LTDA | H68: =IFERROR(__xludf.DUMMYFUNCTION("""COMPUTED_VALUE"""),"DATEN TECNOLOGIA") -> DATEN TECNOLOGIA | I68: =IFERROR(__xludf.DUMMYFUNCTION("""COMPUTED_VALUE"""),"CIF") -> CIF | J68: =IFERROR(__xludf.DUMMYFUNCTION("""COMPUTED_VALUE"""),46321.0) -> 46321 | K68: =IFERROR(__xludf.DUMMYFUNCTION("""COMPUTED_VALUE"""),10.0) -> 10 | L68: =IFERROR(__xludf.DUMMYFUNCTION("""COMPUTED_VALUE"""),1.0) -> 1 | M68: =IFERROR(__xludf.DUMMYFUNCTION("""COMPUTED_VALUE"""),191.58) -> 191.58 | N68: =IFERROR(__xludf.DUMMYFUNCTION("""COMPUTED_VALUE"""),"AUTORIZADO") -> AUTORIZADO | O68: =IFERROR(__xludf.DUMMYFUNCTION("""COMPUTED_VALUE"""),"(sem célula)") -> (sem célula)
B69: =IFERROR(__xludf.DUMMYFUNCTION("""COMPUTED_VALUE"""),46304.0) -> 46304 | C69: =IFERROR(__xludf.DUMMYFUNCTION("""COMPUTED_VALUE"""),"266834274") -> 266834274 | D69: =IFERROR(__xludf.DUMMYFUNCTION("""COMPUTED_VALUE"""),"107262") -> 107262 | E69: =IFERROR(__xludf.DUMMYFUNCTION("""COMPUTED_VALUE"""),"8177617") -> 8177617 | F69: =IFERROR(__xludf.DUMMYFUNCTION("""COMPUTED_VALUE"""),"BAU") -> BAU | G69: =IFERROR(__xludf.DUMMYFUNCTION("""COMPUTED_VALUE"""),"M.F. INFORMATICA") -> M.F. INFORMATICA | H69: =IFERROR(__xludf.DUMMYFUNCTION("""COMPUTED_VALUE"""),"DATEN TECNOLOGIA") -> DATEN TECNOLOGIA | I69: =IFERROR(__xludf.DUMMYFUNCTION("""COMPUTED_VALUE"""),"CIF") -> CIF | J69: =IFERROR(__xludf.DUMMYFUNCTION("""COMPUTED_VALUE"""),46321.0) -> 46321 | K69: =IFERROR(__xludf.DUMMYFUNCTION("""COMPUTED_VALUE"""),10.0) -> 10 | L69: =IFERROR(__xludf.DUMMYFUNCTION("""COMPUTED_VALUE"""),2.0) -> 2 | M69: =IFERROR(__xludf.DUMMYFUNCTION("""COMPUTED_VALUE"""),127.64) -> 127.64 | N69: =IFERROR(__xludf.DUMMYFUNCTION("""COMPUTED_VALUE"""),"AUTORIZADO") -> AUTORIZADO | O69: =IFERROR(__xludf.DUMMYFUNCTION("""COMPUTED_VALUE"""),"(sem célula)") -> (sem célula)
B70: =IFERROR(__xludf.DUMMYFUNCTION("""COMPUTED_VALUE"""),46304.0) -> 46304 | C70: =IFERROR(__xludf.DUMMYFUNCTION("""COMPUTED_VALUE"""),"266834270") -> 266834270 | D70: =IFERROR(__xludf.DUMMYFUNCTION("""COMPUTED_VALUE"""),"107255, 107256, 107261") -> 107255, 107256, 107261 | E70: =IFERROR(__xludf.DUMMYFUNCTION("""COMPUTED_VALUE"""),"8177616") -> 8177616 | F70: =IFERROR(__xludf.DUMMYFUNCTION("""COMPUTED_VALUE"""),"BHZ") -> BHZ | G70: =IFERROR(__xludf.DUMMYFUNCTION("""COMPUTED_VALUE"""),"MOISEIS DA FONSECA LOPES 03704723657") -> MOISEIS DA FONSECA LOPES 03704723657 | H70: =IFERROR(__xludf.DUMMYFUNCTION("""COMPUTED_VALUE"""),"DATEN TECNOLOGIA") -> DATEN TECNOLOGIA | I70: =IFERROR(__xludf.DUMMYFUNCTION("""COMPUTED_VALUE"""),"CIF") -> CIF | J70: =IFERROR(__xludf.DUMMYFUNCTION("""COMPUTED_VALUE"""),46321.0) -> 46321 | K70: =IFERROR(__xludf.DUMMYFUNCTION("""COMPUTED_VALUE"""),10.0) -> 10 | L70: =IFERROR(__xludf.DUMMYFUNCTION("""COMPUTED_VALUE"""),2.0) -> 2 | M70: =IFERROR(__xludf.DUMMYFUNCTION("""COMPUTED_VALUE"""),118.41) -> 118.41 | N70: =IFERROR(__xludf.DUMMYFUNCTION("""COMPUTED_VALUE"""),"AUTORIZADO") -> AUTORIZADO | O70: =IFERROR(__xludf.DUMMYFUNCTION("""COMPUTED_VALUE"""),"(sem célula)") -> (sem célula)
B71: =IFERROR(__xludf.DUMMYFUNCTION("""COMPUTED_VALUE"""),46304.0) -> 46304 | C71: =IFERROR(__xludf.DUMMYFUNCTION("""COMPUTED_VALUE"""),"266834268") -> 266834268 | D71: =IFERROR(__xludf.DUMMYFUNCTION("""COMPUTED_VALUE"""),"107254, 107258") -> 107254, 107258 | E71: =IFERROR(__xludf.DUMMYFUNCTION("""COMPUTED_VALUE"""),"8177622") -> 8177622 | F71: =IFERROR(__xludf.DUMMYFUNCTION("""COMPUTED_VALUE"""),"BSB") -> BSB | G71: =IFERROR(__xludf.DUMMYFUNCTION("""COMPUTED_VALUE"""),"FERNANDO JOSE FERNANDES FILHO 0066122988") -> FERNANDO JOSE FERNANDES FILHO 0066122988 | H71: =IFERROR(__xludf.DUMMYFUNCTION("""COMPUTED_VALUE"""),"DATEN TECNOLOGIA") -> DATEN TECNOLOGIA | I71: =IFERROR(__xludf.DUMMYFUNCTION("""COMPUTED_VALUE"""),"CIF") -> CIF | J71: =IFERROR(__xludf.DUMMYFUNCTION("""COMPUTED_VALUE"""),46321.0) -> 46321 | K71: =IFERROR(__xludf.DUMMYFUNCTION("""COMPUTED_VALUE"""),10.0) -> 10 | L71: =IFERROR(__xludf.DUMMYFUNCTION("""COMPUTED_VALUE"""),1.0) -> 1 | M71: =IFERROR(__xludf.DUMMYFUNCTION("""COMPUTED_VALUE"""),122.47) -> 122.47 | N71: =IFERROR(__xludf.DUMMYFUNCTION("""COMPUTED_VALUE"""),"AUTORIZADO") -> AUTORIZADO | O71: =IFERROR(__xludf.DUMMYFUNCTION("""COMPUTED_VALUE"""),"(sem célula)") -> (sem célula)
B72: =IFERROR(__xludf.DUMMYFUNCTION("""COMPUTED_VALUE"""),46304.0) -> 46304 | C72: =IFERROR(__xludf.DUMMYFUNCTION("""COMPUTED_VALUE"""),"266834265") -> 266834265 | D72: =IFERROR(__xludf.DUMMYFUNCTION("""COMPUTED_VALUE"""),"107277") -> 107277 | E72: =IFERROR(__xludf.DUMMYFUNCTION("""COMPUTED_VALUE"""),"8177620") -> 8177620 | F72: =IFERROR(__xludf.DUMMYFUNCTION("""COMPUTED_VALUE"""),"BUQ") -> BUQ | G72: =IFERROR(__xludf.DUMMYFUNCTION("""COMPUTED_VALUE"""),"MCE MONTAGEM") -> MCE MONTAGEM | H72: =IFERROR(__xludf.DUMMYFUNCTION("""COMPUTED_VALUE"""),"DATEN TECNOLOGIA") -> DATEN TECNOLOGIA | I72: =IFERROR(__xludf.DUMMYFUNCTION("""COMPUTED_VALUE"""),"CIF") -> CIF | J72: =IFERROR(__xludf.DUMMYFUNCTION("""COMPUTED_VALUE"""),46323.0) -> 46323 | K72: =IFERROR(__xludf.DUMMYFUNCTION("""COMPUTED_VALUE"""),12.0) -> 12 | L72: =IFERROR(__xludf.DUMMYFUNCTION("""COMPUTED_VALUE"""),1.0) -> 1 | M72: =IFERROR(__xludf.DUMMYFUNCTION("""COMPUTED_VALUE"""),155.51) -> 155.51 | N72: =IFERROR(__xludf.DUMMYFUNCTION("""COMPUTED_VALUE"""),"AUTORIZADO") -> AUTORIZADO | O72: =IFERROR(__xludf.DUMMYFUNCTION("""COMPUTED_VALUE"""),"FSA-1") -> FSA-1
B73: =IFERROR(__xludf.DUMMYFUNCTION("""COMPUTED_VALUE"""),46304.0) -> 46304 | C73: =IFERROR(__xludf.DUMMYFUNCTION("""COMPUTED_VALUE"""),"266834273") -> 266834273 | D73: =IFERROR(__xludf.DUMMYFUNCTION("""COMPUTED_VALUE"""),"107259") -> 107259 | E73: =IFERROR(__xludf.DUMMYFUNCTION("""COMPUTED_VALUE"""),"8177624") -> 8177624 | F73: =IFERROR(__xludf.DUMMYFUNCTION("""COMPUTED_VALUE"""),"FSA") -> FSA | G73: =IFERROR(__xludf.DUMMYFUNCTION("""COMPUTED_VALUE"""),"KONTTATO INFORMATICA LTDA") -> KONTTATO INFORMATICA LTDA | H73: =IFERROR(__xludf.DUMMYFUNCTION("""COMPUTED_VALUE"""),"DATEN TECNOLOGIA") -> DATEN TECNOLOGIA | I73: =IFERROR(__xludf.DUMMYFUNCTION("""COMPUTED_VALUE"""),"CIF") -> CIF | J73: =IFERROR(__xludf.DUMMYFUNCTION("""COMPUTED_VALUE"""),46317.0) -> 46317 | K73: =IFERROR(__xludf.DUMMYFUNCTION("""COMPUTED_VALUE"""),8.0) -> 8 | L73: =IFERROR(__xludf.DUMMYFUNCTION("""COMPUTED_VALUE"""),1.0) -> 1 | M73: =IFERROR(__xludf.DUMMYFUNCTION("""COMPUTED_VALUE"""),131.21) -> 131.21 | N73: =IFERROR(__xludf.DUMMYFUNCTION("""COMPUTED_VALUE"""),"AUTORIZADO") -> AUTORIZADO | O73: =IFERROR(__xludf.DUMMYFUNCTION("""COMPUTED_VALUE"""),"(sem célula)") -> (sem célula)
B74: =IFERROR(__xludf.DUMMYFUNCTION("""COMPUTED_VALUE"""),46304.0) -> 46304 | C74: =IFERROR(__xludf.DUMMYFUNCTION("""COMPUTED_VALUE"""),"266834263") -> 266834263 | D74: =IFERROR(__xludf.DUMMYFUNCTION("""COMPUTED_VALUE"""),"107278") -> 107278 | E74: =IFERROR(__xludf.DUMMYFUNCTION("""COMPUTED_VALUE"""),"8177619") -> 8177619 | F74: =IFERROR(__xludf.DUMMYFUNCTION("""COMPUTED_VALUE"""),"ITJ") -> ITJ | G74: =IFERROR(__xludf.DUMMYFUNCTION("""COMPUTED_VALUE"""),"EDSON PLINIO") -> EDSON PLINIO | H74: =IFERROR(__xludf.DUMMYFUNCTION("""COMPUTED_VALUE"""),"DATEN TECNOLOGIA") -> DATEN TECNOLOGIA | I74: =IFERROR(__xludf.DUMMYFUNCTION("""COMPUTED_VALUE"""),"CIF") -> CIF | J74: =IFERROR(__xludf.DUMMYFUNCTION("""COMPUTED_VALUE"""),46322.0) -> 46322 | K74: =IFERROR(__xludf.DUMMYFUNCTION("""COMPUTED_VALUE"""),11.0) -> 11 | L74: =IFERROR(__xludf.DUMMYFUNCTION("""COMPUTED_VALUE"""),1.0) -> 1 | M74: =IFERROR(__xludf.DUMMYFUNCTION("""COMPUTED_VALUE"""),139.21) -> 139.21 | N74: =IFERROR(__xludf.DUMMYFUNCTION("""COMPUTED_VALUE"""),"AUTORIZADO") -> AUTORIZADO | O74: =IFERROR(__xludf.DUMMYFUNCTION("""COMPUTED_VALUE"""),"FSA-1") -> FSA-1
B75: =IFERROR(__xludf.DUMMYFUNCTION("""COMPUTED_VALUE"""),46304.0) -> 46304 | C75: =IFERROR(__xludf.DUMMYFUNCTION("""COMPUTED_VALUE"""),"266834267") -> 266834267 | D75: =IFERROR(__xludf.DUMMYFUNCTION("""COMPUTED_VALUE"""),"107225, 107253, 107260") -> 107225, 107253, 107260 | E75: =IFERROR(__xludf.DUMMYFUNCTION("""COMPUTED_VALUE"""),"8177621") -> 8177621 | F75: =IFERROR(__xludf.DUMMYFUNCTION("""COMPUTED_VALUE"""),"MCZ") -> MCZ | G75: =IFERROR(__xludf.DUMMYFUNCTION("""COMPUTED_VALUE"""),"COMPUAL INFORMATICA") -> COMPUAL INFORMATICA | H75: =IFERROR(__xludf.DUMMYFUNCTION("""COMPUTED_VALUE"""),"DATEN TECNOLOGIA") -> DATEN TECNOLOGIA | I75: =IFERROR(__xludf.DUMMYFUNCTION("""COMPUTED_VALUE"""),"CIF") -> CIF | J75: =IFERROR(__xludf.DUMMYFUNCTION("""COMPUTED_VALUE"""),46318.0) -> 46318 | K75: =IFERROR(__xludf.DUMMYFUNCTION("""COMPUTED_VALUE"""),9.0) -> 9 | L75: =IFERROR(__xludf.DUMMYFUNCTION("""COMPUTED_VALUE"""),3.0) -> 3 | M75: =IFERROR(__xludf.DUMMYFUNCTION("""COMPUTED_VALUE"""),85.87) -> 85.87 | N75: =IFERROR(__xludf.DUMMYFUNCTION("""COMPUTED_VALUE"""),"AUTORIZADO") -> AUTORIZADO | O75: =IFERROR(__xludf.DUMMYFUNCTION("""COMPUTED_VALUE"""),"FSA-1") -> FSA-1
B76: =IFERROR(__xludf.DUMMYFUNCTION("""COMPUTED_VALUE"""),46304.0) -> 46304 | C76: =IFERROR(__xludf.DUMMYFUNCTION("""COMPUTED_VALUE"""),"266834266") -> 266834266 | D76: =IFERROR(__xludf.DUMMYFUNCTION("""COMPUTED_VALUE"""),"107242, 107275") -> 107242, 107275 | E76: =IFERROR(__xludf.DUMMYFUNCTION("""COMPUTED_VALUE"""),"8177615") -> 8177615 | F76: =IFERROR(__xludf.DUMMYFUNCTION("""COMPUTED_VALUE"""),"NAT") -> NAT | G76: =IFERROR(__xludf.DUMMYFUNCTION("""COMPUTED_VALUE"""),"W SERVICOS E ASSIST TEC INFORM LTDA") -> W SERVICOS E ASSIST TEC INFORM LTDA | H76: =IFERROR(__xludf.DUMMYFUNCTION("""COMPUTED_VALUE"""),"DATEN TECNOLOGIA") -> DATEN TECNOLOGIA | I76: =IFERROR(__xludf.DUMMYFUNCTION("""COMPUTED_VALUE"""),"CIF") -> CIF | J76: =IFERROR(__xludf.DUMMYFUNCTION("""COMPUTED_VALUE"""),46318.0) -> 46318 | K76: =IFERROR(__xludf.DUMMYFUNCTION("""COMPUTED_VALUE"""),9.0) -> 9 | L76: =IFERROR(__xludf.DUMMYFUNCTION("""COMPUTED_VALUE"""),2.0) -> 2 | M76: =IFERROR(__xludf.DUMMYFUNCTION("""COMPUTED_VALUE"""),96.56) -> 96.56 | N76: =IFERROR(__xludf.DUMMYFUNCTION("""COMPUTED_VALUE"""),"AUTORIZADO") -> AUTORIZADO | O76: =IFERROR(__xludf.DUMMYFUNCTION("""COMPUTED_VALUE"""),"FSA-1") -> FSA-1
B77: =IFERROR(__xludf.DUMMYFUNCTION("""COMPUTED_VALUE"""),46304.0) -> 46304 | C77: =IFERROR(__xludf.DUMMYFUNCTION("""COMPUTED_VALUE"""),"266834275") -> 266834275 | D77: =IFERROR(__xludf.DUMMYFUNCTION("""COMPUTED_VALUE"""),"107263") -> 107263 | E77: =IFERROR(__xludf.DUMMYFUNCTION("""COMPUTED_VALUE"""),"8177625") -> 8177625 | F77: =IFERROR(__xludf.DUMMYFUNCTION("""COMPUTED_VALUE"""),"REC") -> REC | G77: =IFERROR(__xludf.DUMMYFUNCTION("""COMPUTED_VALUE"""),"LUCAS RAMOS SILVA DE OLIVEIRA") -> LUCAS RAMOS SILVA DE OLIVEIRA | H77: =IFERROR(__xludf.DUMMYFUNCTION("""COMPUTED_VALUE"""),"DATEN TECNOLOGIA") -> DATEN TECNOLOGIA | I77: =IFERROR(__xludf.DUMMYFUNCTION("""COMPUTED_VALUE"""),"CIF") -> CIF | J77: =IFERROR(__xludf.DUMMYFUNCTION("""COMPUTED_VALUE"""),46318.0) -> 46318 | K77: =IFERROR(__xludf.DUMMYFUNCTION("""COMPUTED_VALUE"""),9.0) -> 9 | L77: =IFERROR(__xludf.DUMMYFUNCTION("""COMPUTED_VALUE"""),1.0) -> 1 | M77: =IFERROR(__xludf.DUMMYFUNCTION("""COMPUTED_VALUE"""),173.6) -> 173.6 | N77: =IFERROR(__xludf.DUMMYFUNCTION("""COMPUTED_VALUE"""),"AUTORIZADO") -> AUTORIZADO | O77: =IFERROR(__xludf.DUMMYFUNCTION("""COMPUTED_VALUE"""),"FSA-1") -> FSA-1
B78: =IFERROR(__xludf.DUMMYFUNCTION("""COMPUTED_VALUE"""),46304.0) -> 46304 | C78: =IFERROR(__xludf.DUMMYFUNCTION("""COMPUTED_VALUE"""),"266834271") -> 266834271 | D78: =IFERROR(__xludf.DUMMYFUNCTION("""COMPUTED_VALUE"""),"107257") -> 107257 | E78: =IFERROR(__xludf.DUMMYFUNCTION("""COMPUTED_VALUE"""),"8177623") -> 8177623 | F78: =IFERROR(__xludf.DUMMYFUNCTION("""COMPUTED_VALUE"""),"RIO") -> RIO | G78: =IFERROR(__xludf.DUMMYFUNCTION("""COMPUTED_VALUE"""),"PRO 200 INFORMATICA LTDA") -> PRO 200 INFORMATICA LTDA | H78: =IFERROR(__xludf.DUMMYFUNCTION("""COMPUTED_VALUE"""),"DATEN TECNOLOGIA") -> DATEN TECNOLOGIA | I78: =IFERROR(__xludf.DUMMYFUNCTION("""COMPUTED_VALUE"""),"CIF") -> CIF | J78: =IFERROR(__xludf.DUMMYFUNCTION("""COMPUTED_VALUE"""),46321.0) -> 46321 | K78: =IFERROR(__xludf.DUMMYFUNCTION("""COMPUTED_VALUE"""),10.0) -> 10 | L78: =IFERROR(__xludf.DUMMYFUNCTION("""COMPUTED_VALUE"""),1.0) -> 1 | M78: =IFERROR(__xludf.DUMMYFUNCTION("""COMPUTED_VALUE"""),103.77) -> 103.77 | N78: =IFERROR(__xludf.DUMMYFUNCTION("""COMPUTED_VALUE"""),"AUTORIZADO") -> AUTORIZADO | O78: =IFERROR(__xludf.DUMMYFUNCTION("""COMPUTED_VALUE"""),"(sem célula)") -> (sem célula)

Sheet DESTINOS
A1: Prazo e volume por destino
A2: Respeita todos os filtros da aba DASH. Prazo em dias, conforme o sistema.
A4: =IFERROR(__xludf.DUMMYFUNCTION("IFERROR(QUERY(DADOS!$A$1:$V$5001,""select Col4, count(Col7), sum(Col17), sum(Col16), avg(Col3), min(Col3), max(Col3) where Col22 = true and Col4 <> '' group by Col4 order by count(Col7) desc, Col4 label Col4 'Destino', count(Col7) 'CT-es', sum(Col17) 'Vol"&"umes', sum(Col16) 'Frete (R$)', avg(Col3) 'Prazo médio (dias)', min(Col3) 'Prazo mín.', max(Col3) 'Prazo máx.'"",1),""Nenhum registro"")"),"Destino") -> Destino | B4: =IFERROR(__xludf.DUMMYFUNCTION("""COMPUTED_VALUE"""),"CT-es") -> CT-es | C4: =IFERROR(__xludf.DUMMYFUNCTION("""COMPUTED_VALUE"""),"Volumes") -> Volumes | D4: =IFERROR(__xludf.DUMMYFUNCTION("""COMPUTED_VALUE"""),"Frete (R$)") -> Frete (R$) | E4: =IFERROR(__xludf.DUMMYFUNCTION("""COMPUTED_VALUE"""),"Prazo médio (dias)") -> Prazo médio (dias) | F4: =IFERROR(__xludf.DUMMYFUNCTION("""COMPUTED_VALUE"""),"Prazo mín.") -> Prazo mín. | G4: =IFERROR(__xludf.DUMMYFUNCTION("""COMPUTED_VALUE"""),"Prazo máx.") -> Prazo máx.
A5: =IFERROR(__xludf.DUMMYFUNCTION("""COMPUTED_VALUE"""),"ABS") -> ABS | B5: =IFERROR(__xludf.DUMMYFUNCTION("""COMPUTED_VALUE"""),1.0) -> 1 | C5: =IFERROR(__xludf.DUMMYFUNCTION("""COMPUTED_VALUE"""),1.0) -> 1 | D5: =IFERROR(__xludf.DUMMYFUNCTION("""COMPUTED_VALUE"""),191.58) -> 191.58 | E5: =IFERROR(__xludf.DUMMYFUNCTION("""COMPUTED_VALUE"""),10.0) -> 10 | F5: =IFERROR(__xludf.DUMMYFUNCTION("""COMPUTED_VALUE"""),10.0) -> 10 | G5: =IFERROR(__xludf.DUMMYFUNCTION("""COMPUTED_VALUE"""),10.0) -> 10
A6: =IFERROR(__xludf.DUMMYFUNCTION("""COMPUTED_VALUE"""),"BAU") -> BAU | B6: =IFERROR(__xludf.DUMMYFUNCTION("""COMPUTED_VALUE"""),1.0) -> 1 | C6: =IFERROR(__xludf.DUMMYFUNCTION("""COMPUTED_VALUE"""),2.0) -> 2 | D6: =IFERROR(__xludf.DUMMYFUNCTION("""COMPUTED_VALUE"""),127.64) -> 127.64 | E6: =IFERROR(__xludf.DUMMYFUNCTION("""COMPUTED_VALUE"""),10.0) -> 10 | F6: =IFERROR(__xludf.DUMMYFUNCTION("""COMPUTED_VALUE"""),10.0) -> 10 | G6: =IFERROR(__xludf.DUMMYFUNCTION("""COMPUTED_VALUE"""),10.0) -> 10
A7: =IFERROR(__xludf.DUMMYFUNCTION("""COMPUTED_VALUE"""),"BHZ") -> BHZ | B7: =IFERROR(__xludf.DUMMYFUNCTION("""COMPUTED_VALUE"""),1.0) -> 1 | C7: =IFERROR(__xludf.DUMMYFUNCTION("""COMPUTED_VALUE"""),2.0) -> 2 | D7: =IFERROR(__xludf.DUMMYFUNCTION("""COMPUTED_VALUE"""),118.41) -> 118.41 | E7: =IFERROR(__xludf.DUMMYFUNCTION("""COMPUTED_VALUE"""),10.0) -> 10 | F7: =IFERROR(__xludf.DUMMYFUNCTION("""COMPUTED_VALUE"""),10.0) -> 10 | G7: =IFERROR(__xludf.DUMMYFUNCTION("""COMPUTED_VALUE"""),10.0) -> 10
A8: =IFERROR(__xludf.DUMMYFUNCTION("""COMPUTED_VALUE"""),"BSB") -> BSB | B8: =IFERROR(__xludf.DUMMYFUNCTION("""COMPUTED_VALUE"""),1.0) -> 1 | C8: =IFERROR(__xludf.DUMMYFUNCTION("""COMPUTED_VALUE"""),1.0) -> 1 | D8: =IFERROR(__xludf.DUMMYFUNCTION("""COMPUTED_VALUE"""),122.47) -> 122.47 | E8: =IFERROR(__xludf.DUMMYFUNCTION("""COMPUTED_VALUE"""),10.0) -> 10 | F8: =IFERROR(__xludf.DUMMYFUNCTION("""COMPUTED_VALUE"""),10.0) -> 10 | G8: =IFERROR(__xludf.DUMMYFUNCTION("""COMPUTED_VALUE"""),10.0) -> 10
A9: =IFERROR(__xludf.DUMMYFUNCTION("""COMPUTED_VALUE"""),"BUQ") -> BUQ | B9: =IFERROR(__xludf.DUMMYFUNCTION("""COMPUTED_VALUE"""),1.0) -> 1 | C9: =IFERROR(__xludf.DUMMYFUNCTION("""COMPUTED_VALUE"""),1.0) -> 1 | D9: =IFERROR(__xludf.DUMMYFUNCTION("""COMPUTED_VALUE"""),155.51) -> 155.51 | E9: =IFERROR(__xludf.DUMMYFUNCTION("""COMPUTED_VALUE"""),12.0) -> 12 | F9: =IFERROR(__xludf.DUMMYFUNCTION("""COMPUTED_VALUE"""),12.0) -> 12 | G9: =IFERROR(__xludf.DUMMYFUNCTION("""COMPUTED_VALUE"""),12.0) -> 12
A10: =IFERROR(__xludf.DUMMYFUNCTION("""COMPUTED_VALUE"""),"FSA") -> FSA | B10: =IFERROR(__xludf.DUMMYFUNCTION("""COMPUTED_VALUE"""),1.0) -> 1 | C10: =IFERROR(__xludf.DUMMYFUNCTION("""COMPUTED_VALUE"""),1.0) -> 1 | D10: =IFERROR(__xludf.DUMMYFUNCTION("""COMPUTED_VALUE"""),131.21) -> 131.21 | E10: =IFERROR(__xludf.DUMMYFUNCTION("""COMPUTED_VALUE"""),8.0) -> 8 | F10: =IFERROR(__xludf.DUMMYFUNCTION("""COMPUTED_VALUE"""),8.0) -> 8 | G10: =IFERROR(__xludf.DUMMYFUNCTION("""COMPUTED_VALUE"""),8.0) -> 8
A11: =IFERROR(__xludf.DUMMYFUNCTION("""COMPUTED_VALUE"""),"ITJ") -> ITJ | B11: =IFERROR(__xludf.DUMMYFUNCTION("""COMPUTED_VALUE"""),1.0) -> 1 | C11: =IFERROR(__xludf.DUMMYFUNCTION("""COMPUTED_VALUE"""),1.0) -> 1 | D11: =IFERROR(__xludf.DUMMYFUNCTION("""COMPUTED_VALUE"""),139.21) -> 139.21 | E11: =IFERROR(__xludf.DUMMYFUNCTION("""COMPUTED_VALUE"""),11.0) -> 11 | F11: =IFERROR(__xludf.DUMMYFUNCTION("""COMPUTED_VALUE"""),11.0) -> 11 | G11: =IFERROR(__xludf.DUMMYFUNCTION("""COMPUTED_VALUE"""),11.0) -> 11
A12: =IFERROR(__xludf.DUMMYFUNCTION("""COMPUTED_VALUE"""),"MCZ") -> MCZ | B12: =IFERROR(__xludf.DUMMYFUNCTION("""COMPUTED_VALUE"""),1.0) -> 1 | C12: =IFERROR(__xludf.DUMMYFUNCTION("""COMPUTED_VALUE"""),3.0) -> 3 | D12: =IFERROR(__xludf.DUMMYFUNCTION("""COMPUTED_VALUE"""),85.87) -> 85.87 | E12: =IFERROR(__xludf.DUMMYFUNCTION("""COMPUTED_VALUE"""),9.0) -> 9 | F12: =IFERROR(__xludf.DUMMYFUNCTION("""COMPUTED_VALUE"""),9.0) -> 9 | G12: =IFERROR(__xludf.DUMMYFUNCTION("""COMPUTED_VALUE"""),9.0) -> 9
A13: =IFERROR(__xludf.DUMMYFUNCTION("""COMPUTED_VALUE"""),"NAT") -> NAT | B13: =IFERROR(__xludf.DUMMYFUNCTION("""COMPUTED_VALUE"""),1.0) -> 1 | C13: =IFERROR(__xludf.DUMMYFUNCTION("""COMPUTED_VALUE"""),2.0) -> 2 | D13: =IFERROR(__xludf.DUMMYFUNCTION("""COMPUTED_VALUE"""),96.56) -> 96.56 | E13: =IFERROR(__xludf.DUMMYFUNCTION("""COMPUTED_VALUE"""),9.0) -> 9 | F13: =IFERROR(__xludf.DUMMYFUNCTION("""COMPUTED_VALUE"""),9.0) -> 9 | G13: =IFERROR(__xludf.DUMMYFUNCTION("""COMPUTED_VALUE"""),9.0) -> 9
A14: =IFERROR(__xludf.DUMMYFUNCTION("""COMPUTED_VALUE"""),"REC") -> REC | B14: =IFERROR(__xludf.DUMMYFUNCTION("""COMPUTED_VALUE"""),1.0) -> 1 | C14: =IFERROR(__xludf.DUMMYFUNCTION("""COMPUTED_VALUE"""),1.0) -> 1 | D14: =IFERROR(__xludf.DUMMYFUNCTION("""COMPUTED_VALUE"""),173.6) -> 173.6 | E14: =IFERROR(__xludf.DUMMYFUNCTION("""COMPUTED_VALUE"""),9.0) -> 9 | F14: =IFERROR(__xludf.DUMMYFUNCTION("""COMPUTED_VALUE"""),9.0) -> 9 | G14: =IFERROR(__xludf.DUMMYFUNCTION("""COMPUTED_VALUE"""),9.0) -> 9
A15: =IFERROR(__xludf.DUMMYFUNCTION("""COMPUTED_VALUE"""),"RIO") -> RIO | B15: =IFERROR(__xludf.DUMMYFUNCTION("""COMPUTED_VALUE"""),1.0) -> 1 | C15: =IFERROR(__xludf.DUMMYFUNCTION("""COMPUTED_VALUE"""),1.0) -> 1 | D15: =IFERROR(__xludf.DUMMYFUNCTION("""COMPUTED_VALUE"""),103.77) -> 103.77 | E15: =IFERROR(__xludf.DUMMYFUNCTION("""COMPUTED_VALUE"""),10.0) -> 10 | F15: =IFERROR(__xludf.DUMMYFUNCTION("""COMPUTED_VALUE"""),10.0) -> 10 | G15: =IFERROR(__xludf.DUMMYFUNCTION("""COMPUTED_VALUE"""),10.0) -> 10

Sheet BASE
A1: Modal | B1: STATUS | C1: Status Desc | D1: CT-e | E1: StatusCT-e | F1: PRAZO | G1: ORIG | H1: DEST | I1: AWB | J1: ID Conhec | K1: DATA | L1: DT. PREV. ENTREGA | M1: PRAZO CORRIGIDO | N1: RT.ENTREGA | O1: PRAZO | P1: REVERSA | Q1: DATA ULT. OCOR. | R1: CÉLULA | S1: TIPO FRETE | T1: Estrelado | U1: Pago | V1: VALOR DO FRETE | W1: VOL. | X1: REMETENTE | Y1: DESTINATARIO | Z1: CONSIGNATARIO | AA1: NOTAS | AB1: Filial - Agrupador | AC1: Categoria de Embarque (EDI)
A2: RODO | B2: 6 | C2: NA ORIGEM | D2: N | F2: Antes Prazo | G2: ITN | H2: ITN | I2: 946 | J2: 266801541 | K2: 46304 | L2: 46314 | N2: 1 | O2: 5 | P2: N | S2: CIF | T2: N | U2: N | V2: 34.87 | W2: 3 | X2: TRIFIL | Y2: JAM E JÚ CINQUENTENARIO | AA2: 1302858 | AC2: B2B
A3: RODO | B3: 6 | C3: NA ORIGEM | D3: N | F3: Antes Prazo | G3: ITN | H3: SAO | I3: 8176609 | J3: 266801850 | K3: 46304 | L3: 46316 | N3: 34 | O3: 7 | P3: N | R3: SAO-1 | S3: CSG | T3: N | U3: N | V3: 1 | W3: 1 | X3: TRIFIL | Y3: ACHE LABORATORIOS FARMACEUTICOS SA | AA3: 70000284
A4: RODO | B4: 6 | C4: NA ORIGEM | D4: S | E4: AUTORIZADO | F4: Antes Prazo | G4: ITN | H4: ATB | I4: 8177101 | J4: 266802183 | K4: 46304 | L4: 46317 | N4: 103 | O4: 8 | P4: N | R4: SAO-1 | S4: CIF | T4: N | U4: N | V4: 38.46 | W4: 3 | X4: TRIFIL | Y4: LOJAS EDLOPES | AA4: 1306031 | AC4: B2B
A5: RODO | B5: 6 | C5: NA ORIGEM | D5: S | E5: AUTORIZADO | F5: Antes Prazo | G5: ITN | H5: MMG | I5: 8177082 | J5: 266802184 | K5: 46304 | L5: 46317 | N5: 40 | O5: 8 | P5: N | R5: SAO-1 | S5: CIF | T5: N | U5: N | V5: 38.46 | W5: 2 | X5: TRIFIL | Y5: BELLAS MEIAS E LINGERIES LTDA | AA5: 1305597 | AC5: B2B
A6: RODO | B6: 6 | C6: NA ORIGEM | D6: S | E6: AUTORIZADO | F6: Antes Prazo | G6: ITN | H6: SJP | I6: 8177106 | J6: 266802185 | K6: 46304 | L6: 46317 | N6: 101 | O6: 8 | P6: N | R6: SAO-1 | S6: CIF | T6: N | U6: N | V6: 136.07 | W6: 37 | X6: TRIFIL | Y6: VIVIANE REBECA DE FREITAS FIRME | AA6: 1306021 | AC6: B2B
A7: RODO | B7: 6 | C7: NA ORIGEM | D7: S | E7: AUTORIZADO | F7: Antes Prazo | G7: ITN | H7: AQA | I7: 8177107 | J7: 266802186 | K7: 46304 | L7: 46316 | N7: 2 | O7: 7 | P7: N | R7: SAO-1 | S7: CIF | T7: N | U7: N | V7: 310.68 | W7: 56 | X7: TRIFIL | Y7: LOJAS LUPO | AA7: 1304628 | AC7: B2B
A8: RODO | B8: 6 | C8: NA ORIGEM | D8: S | E8: AUTORIZADO | F8: Antes Prazo | G8: ITN | H8: SOD | I8: 8177083 | J8: 266802187 | K8: 46304 | L8: 46323 | N8: 107 | O8: 12 | P8: N | R8: SAO-1 | S8: CIF | T8: N | U8: N | V8: 38.46 | W8: 3 | X8: TRIFIL | Y8: MASTHER VARIEDADES LTDA | AA8: 1305607 | AC8: B2B
A9: RODO | B9: 6 | C9: NA ORIGEM | D9: S | E9: AUTORIZADO | F9: Antes Prazo | G9: ITN | H9: SOD | I9: 8177084 | J9: 266802188 | K9: 46304 | L9: 46317 | N9: 104 | O9: 8 | P9: N | R9: SAO-1 | S9: CIF | T9: N | U9: N | V9: 38.46 | W9: 2 | X9: TRIFIL | Y9: MILENE PEDROSO FAVARO ME | AA9: 1305858 | AC9: B2B
A10: RODO | B10: 6 | C10: NA ORIGEM | D10: S | E10: AUTORIZADO | F10: Antes Prazo | G10: ITN | H10: RIO | I10: 8177078 | J10: 266802189 | K10: 46304 | L10: 46316 | N10: 62 | O10: 7 | P10: N | S10: CIF | T10: N | U10: N | V10: 69.49 | W10: 1 | X10: TRIFIL | Y10: H. V. MODAS LTDA - ME | AA10: 1305850 | AC10: B2B
A11: RODO | B11: 6 | C11: NA ORIGEM | D11: S | E11: AUTORIZADO | F11: Antes Prazo | G11: ITN | H11: BHZ | I11: 8177085 | J11: 266802190 | K11: 46304 | L11: 46316 | N11: 2 | O11: 7 | P11: N | S11: CIF | T11: N | U11: N | V11: 66.52 | W11: 7 | X11: TRIFIL | Y11: LUPO | AA11: 1305803 | AC11: B2B
A12: RODO | B12: 6 | C12: NA ORIGEM | D12: S | E12: AUTORIZADO | F12: Antes Prazo | G12: ITN | H12: BCG | I12: 8177102 | J12: 266802191 | K12: 46304 | L12: 46318 | N12: 127 | O12: 9 | P12: N | S12: CIF | T12: N | U12: N | V12: 51.62 | W12: 5 | X12: TRIFIL | Y12: MARIA DALVA FERREIRA DOS SANTOS | AA12: 1306008 | AC12: B2B
A13: RODO | B13: 6 | C13: NA ORIGEM | D13: S | E13: AUTORIZADO | F13: Antes Prazo | G13: ITN | H13: JDF | I13: 8177103 | J13: 266802192 | K13: 46304 | L13: 46322 | N13: 103 | O13: 11 | P13: N | S13: CIF | T13: N | U13: N | V13: 49.43 | W13: 2 | X13: TRIFIL | Y13: ELENICE GOMES E CIA | AA13: 1306003 | AC13: B2B
A14: RODO | B14: 6 | C14: NA ORIGEM | D14: S | E14: AUTORIZADO | F14: Antes Prazo | G14: ITN | H14: VAG | I14: 8177104 | J14: 266802193 | K14: 46304 | L14: 46321 | N14: 102 | O14: 10 | P14: N | S14: CIF | T14: N | U14: N | V14: 61.68 | W14: 8 | X14: TRIFIL | Y14: JO MODAS LTDA ME - 2031 1 9 | AA14: 1306020 | AC14: B2B
A15: RODO | B15: 6 | C15: NA ORIGEM | D15: S | E15: AUTORIZADO | F15: Antes Prazo | G15: ITN | H15: MOC | I15: 8177086 | J15: 266802195 | K15: 46304 | L15: 46322 | N15: 102 | O15: 11 | P15: N | S15: CIF | T15: N | U15: N | V15: 49.43 | W15: 2 | X15: TRIFIL | Y15: LIDIANE ANTUNES DE OLIVEIRA | AA15: 1305622 | AC15: B2B
A16: RODO | B16: 6 | C16: NA ORIGEM | D16: S | E16: AUTORIZADO | F16: Antes Prazo | G16: ITN | H16: FSA | I16: 8177087 | J16: 266802197 | K16: 46304 | L16: 46323 | N16: 217 | O16: 12 | P16: N | S16: CIF | T16: N | U16: N | V16: 37.78 | W16: 1 | X16: TRIFIL | Y16: MARIA IZABEL DA COSTA MATOS - ME | AA16: 1305600 | AC16: B2B
A17: RODO | B17: 6 | C17: NA ORIGEM | D17: S | E17: AUTORIZADO | F17: Antes Prazo | G17: ITN | H17: REC | I17: 8177088 | J17: 266802204 | K17: 46304 | L17: 46321 | N17: 108 | O17: 10 | P17: N | R17: FSA-1 | S17: CIF | T17: N | U17: N | V17: 63.12 | W17: 2 | X17: TRIFIL | Y17: MAGALY MALHAS LTDA-ME. | AA17: 1305857 | AC17: B2B
A18: RODO | B18: 6 | C18: NA ORIGEM | D18: S | E18: AUTORIZADO | F18: Antes Prazo | G18: ITN | H18: MCZ | I18: 8177108 | J18: 266802206 | K18: 46304 | L18: 46316 | N18: 101 | O18: 7 | P18: N | R18: FSA-1 | S18: CIF | T18: N | U18: N | V18: 183.84 | W18: 24 | X18: TRIFIL | Y18: E MANOEL DE MELO | AA18: 1306056 | AC18: B2B
A19: RODO | B19: 6 | C19: NA ORIGEM | D19: S | E19: AUTORIZADO | F19: Antes Prazo | G19: ITN | H19: FOR | I19: 8177089 | J19: 266802207 | K19: 46304 | L19: 46315 | N19: 23 | O19: 6 | P19: N | R19: FSA-1 | S19: CIF | T19: N | U19: N | V19: 64.23 | W19: 1 | X19: TRIFIL | Y19: A.S. ANDRIANI COMERCIO DE VESTUARIO LTDA | AA19: 1305606 | AC19: B2B
A20: RODO | B20: 6 | C20: NA ORIGEM | D20: S | E20: AUTORIZADO | F20: Antes Prazo | G20: ITN | H20: FOR | I20: 8177079 | J20: 266802209 | K20: 46304 | L20: 46315 | N20: 1 | O20: 6 | P20: N | R20: FSA-1 | S20: CIF | T20: N | U20: N | V20: 64.23 | W20: 1 | X20: TRIFIL | Y20: VRA COMERCIO DE VESTUÁRIO LTDA EPP | AA20: 1305834 | AC20: B2B
A21: RODO | B21: 6 | C21: NA ORIGEM | D21: S | E21: AUTORIZADO | F21: Antes Prazo | G21: ITN | H21: FOR | I21: 8177090 | J21: 266802211 | K21: 46304 | L21: 46315 | N21: 16 | O21: 6 | P21: N | R21: FSA-1 | S21: CIF | T21: N | U21: N | V21: 64.23 | W21: 1 | X21: TRIFIL | Y21: ASA COMERCIO DE VESTUARIO LTDA. | AA21: 1305627 | AC21: B2B
A22: RODO | B22: 6 | C22: NA ORIGEM | D22: S | E22: AUTORIZADO | F22: Antes Prazo | G22: ITN | H22: FOR | I22: 8177091 | J22: 266802213 | K22: 46304 | L22: 46316 | N22: 104 | O22: 7 | P22: N | R22: FSA-1 | S22: CIF | T22: N | U22: N | V22: 64.23 | W22: 1 | X22: TRIFIL | Y22: EUSEBIO MEIAS ARTIGOS DE VESTUARIO | AA22: 1305634 | AC22: B2B
A23: RODO | B23: 6 | C23: NA ORIGEM | D23: S | E23: AUTORIZADO | F23: Antes Prazo | G23: ITN | H23: FOR | I23: 8177092 | J23: 266802214 | K23: 46304 | L23: 46316 | N23: 27 | O23: 7 | P23: N | R23: FSA-1 | S23: CIF | T23: N | U23: N | V23: 64.23 | W23: 1 | X23: TRIFIL | Y23: TERRAZO MEIAS ARTIGOS DO VESTUARIO | AA23: 1305602 | AC23: B2B
A24: RODO | B24: 6 | C24: NA ORIGEM | D24: S | E24: AUTORIZADO | F24: Antes Prazo | G24: ITN | H24: JDO | I24: 8177093 | J24: 266802215 | K24: 46304 | L24: 46315 | N24: 4 | O24: 6 | P24: N | R24: FSA-1 | S24: CIF | T24: N | U24: N | V24: 51.54 | W24: 1 | X24: TRIFIL | Y24: GADELHA COMERCIO DE VESTUARIO LTDA. | AA24: 1305561 | AC24: B2B
A25: RODO | B25: 6 | C25: NA ORIGEM | D25: S | E25: AUTORIZADO | F25: Antes Prazo | G25: ITN | H25: PCS | I25: 8177094 | J25: 266802216 | K25: 46304 | L25: 46324 | N25: 103 | O25: 13 | P25: N | R25: FSA-1 | S25: CIF | T25: N | U25: N | V25: 71.9 | W25: 2 | X25: TRIFIL | Y25: VERSALE COMERCIO DE ARTIGOS DO VESTUARIO | AA25: 1305599 | AC25: B2B
A26: RODO | B26: 6 | C26: NA ORIGEM | D26: S | E26: AUTORIZADO | F26: Antes Prazo | G26: ITN | H26: TUR | I26: 8177095 | J26: 266802217 | K26: 46304 | L26: 46335 | N26: 500 | O26: 19 | P26: N | R26: FSA-1 | S26: CIF | T26: N | U26: N | V26: 71.87 | W26: 5 | X26: TRIFIL | Y26: M N E SILVA & COMPANIA LTDA ME | AA26: 1305818 | AC26: B2B
A27: RODO | B27: 6 | C27: NA ORIGEM | D27: S | E27: AUTORIZADO | F27: Antes Prazo | G27: ITN | H27: NBL | I27: 8177068 | J27: 266802218 | K27: 46304 | L27: 46332 | N27: 902 | O27: 18 | P27: N | R27: FSA-1 | S27: CIF | T27: N | U27: N | V27: 203.43 | W27: 1 | X27: TRIFIL | Y27: L. M. R. SANTOS - ME(0001006261) | AA27: 1305240 | AC27: B2B
A28: RODO | B28: 6 | C28: NA ORIGEM | D28: S | E28: AUTORIZADO | F28: Antes Prazo | G28: ITN | H28: NBL | I28: 8177069 | J28: 266802219 | K28: 46304 | L28: 46332 | N28: 902 | O28: 18 | P28: N | R28: FSA-1 | S28: CIF | T28: N | U28: N | V28: 203.43 | W28: 3 | X28: TRIFIL | Y28: M.O.SILVA-ME(0001025358) | AA28: 1304675 | AC28: B2B
A29: RODO | B29: 6 | C29: NA ORIGEM | D29: S | E29: AUTORIZADO | F29: Antes Prazo | G29: ITN | H29: NBL | I29: 8177070 | J29: 266802220 | K29: 46304 | L29: 46332 | N29: 902 | O29: 18 | P29: N | R29: FSA-1 | S29: CIF | T29: N | U29: N | V29: 353.85 | W29: 13 | X29: TRIFIL | Y29: M.A.M.SOUZA FEITOSA(0001006436) | AA29: 1305268 | AC29: B2B
A30: RODO | B30: 6 | C30: NA ORIGEM | D30: S | E30: AUTORIZADO | F30: Antes Prazo | G30: ITN | H30: NBL | I30: 8177071 | J30: 266802221 | K30: 46304 | L30: 46332 | N30: 902 | O30: 18 | P30: N | S30: CIF | T30: N | U30: N | V30: 203.43 | W30: 1 | X30: TRIFIL | Y30: S S DE ARAUJO ME | AA30: 1304849 | AC30: B2B
A31: RODO | B31: 6 | C31: NA ORIGEM | D31: S | E31: AUTORIZADO | F31: Antes Prazo | G31: ITN | H31: MAO | I31: 8177072 | J31: 266802222 | K31: 46304 | L31: 46344 | N31: 2 | O31: 26 | P31: N | S31: CIF | T31: N | U31: N | V31: 118.27 | W31: 1 | X31: TRIFIL | Y31: N. T. DE CASTRO BRITO LTDA | AA31: 1305190 | AC31: B2B
A32: RODO | B32: 6 | C32: NA ORIGEM | D32: S | E32: AUTORIZADO | F32: Antes Prazo | G32: ITN | H32: MAO | I32: 8177073 | J32: 266802223 | K32: 46304 | L32: 46344 | N32: 2 | O32: 26 | P32: N | R32: SAO-1 | S32: CIF | T32: N | U32: N | V32: 135.22 | W32: 3 | X32: TRIFIL | Y32: J F DA COSTA LIMA | AA32: 1303667 | AC32: B2B
A33: RODO | B33: 6 | C33: NA ORIGEM | D33: S | E33: AUTORIZADO | F33: Antes Prazo | G33: ITN | H33: MAO | I33: 8177074 | J33: 266802224 | K33: 46304 | L33: 46344 | N33: 4 | O33: 26 | P33: N | R33: SAO-1 | S33: CIF | T33: N | U33: N | V33: 317.02 | W33: 13 | X33: TRIFIL | Y33: ARLISON M DE SOUZA | AA33: 1304781 | AC33: B2B
A34: RODO | B34: 6 | C34: NA ORIGEM | D34: S | E34: AUTORIZADO | F34: Antes Prazo | G34: ITN | H34: RBR | I34: 8177075 | J34: 266802225 | K34: 46304 | L34: 46359 | N34: 101 | O34: 36 | P34: N | R34: SAO-1 | S34: CIF | T34: N | U34: N | V34: 130.9 | W34: 2 | X34: TRIFIL | Y34: PJ M MENDONÇA | AA34: 1305112 | AC34: B2B
A35: RODO | B35: 6 | C35: NA ORIGEM | D35: S | E35: AUTORIZADO | F35: Antes Prazo | G35: ITN | H35: RBR | I35: 8177076 | J35: 266802226 | K35: 46304 | L35: 46366 | N35: 103 | O35: 41 | P35: N | R35: SAO-1 | S35: CIF | T35: N | U35: N | V35: 130.9 | W35: 3 | X35: TRIFIL | Y35: M.E FRANCA PINHEIRO | AA35: 1305261 | AC35: B2B
A36: RODO | B36: 6 | C36: NA ORIGEM | D36: S | E36: AUTORIZADO | F36: Antes Prazo | G36: ITN | H36: PVH | I36: 8177077 | J36: 266802227 | K36: 46304 | L36: 46342 | N36: 1 | O36: 24 | P36: N | R36: SAO-1 | S36: CIF | T36: N | U36: N | V36: 119.2 | W36: 1 | X36: TRIFIL | Y36: ATACADAO POPULAR | AA36: 1303067 | AC36: B2B
A37: RODO | B37: 6 | C37: NA ORIGEM | D37: S | E37: AUTORIZADO | F37: Antes Prazo | G37: ITN | H37: CWB | I37: 8177096 | J37: 266802228 | K37: 46304 | L37: 46316 | N37: 6 | O37: 7 | P37: N | R37: FSA-1 | S37: CIF | T37: N | U37: N | V37: 55.69 | W37: 4 | X37: TRIFIL | Y37: XV MEIAS COMERCIO DE CONFECCOES LTD | AA37: 1306078 | AC37: B2B
A38: RODO | B38: 6 | C38: NA ORIGEM | D38: S | E38: AUTORIZADO | F38: Antes Prazo | G38: ITN | H38: CWB | I38: 8177097 | J38: 266802229 | K38: 46304 | L38: 46316 | N38: 19 | O38: 7 | P38: N | R38: FSA-1 | S38: CIF | T38: N | U38: N | V38: 60.6 | W38: 5 | X38: TRIFIL | Y38: LUPO SHOPPING CRYSTAL | AA38: 1305652 | AC38: B2B
A39: RODO | B39: 6 | C39: NA ORIGEM | D39: S | E39: AUTORIZADO | F39: Antes Prazo | G39: ITN | H39: GPB | I39: 8177098 | J39: 266802230 | K39: 46304 | L39: 46325 | N39: 102 | O39: 14 | P39: N | R39: FSA-1 | S39: CIF | T39: N | U39: N | V39: 62.65 | W39: 4 | X39: TRIFIL | Y39: POLO MULTIMARCAS LTDA | AA39: 1305832 | AC39: B2B
A40: RODO | B40: 6 | C40: NA ORIGEM | D40: S | E40: AUTORIZADO | F40: Antes Prazo | G40: ITN | H40: JOI | I40: 8177080 | J40: 266802231 | K40: 46304 | L40: 46323 | N40: 104 | O40: 12 | P40: N | R40: FSA-1 | S40: CIF | T40: N | U40: N | V40: 90.12 | W40: 17 | X40: TRIFIL | Y40: MAFRA CENTER COMERCIO DE ROUPAS EIRELI M | AA40: 1305777 | AC40: B2B
...

Sheet COMO USAR
A1: COMO USAR
A3: Rotina diária
A4: 1. Menu "📦 Emissões" > "Limpar BASE (antes de colar a nova)".
A5: 2. Na aba BASE, clique na célula A1 e cole a planilha do sistema (com o cabeçalho). Alternativa: Arquivo > Importar > Fazer upload > "Substituir dados a partir da célula selecionada" com a A1 selecionada.
A6: 3. Volte para a DASH. Tudo recalcula sozinho.
A8: Importante
A9: • Nunca exclua linhas ou colunas da BASE — apenas limpe o conteúdo (use o menu). Excluir linhas quebra as fórmulas.
A10: • Não digite nas abas DADOS, CALC e LISTAS: são fórmulas.
A11: • Filtros ficam na linha amarela da DASH. "Todos" ou vazio = sem filtro. Menu "Limpar filtros" volta tudo ao padrão.
A12: • A busca livre procura em ID Conhec, NF, AWB, destinatário, remetente, destino e rota de entrega.
A13: • O dashboard lê até 5.000 linhas. A linha de status no topo da DASH avisa se o layout da base mudar.
A14: • Prazo (dias) é o valor do sistema (coluna PRAZO numérica). A coluna "PRAZO CORRIGIDO" ainda não é usada.

Sheet DADOS
A1: Emissão | B1: Prev. Entrega | C1: Prazo (dias) | D1: Destino | E1: Destinatário | F1: Remetente | G1: ID Conhec | H1: NF | I1: AWB | J1: Tipo Frete | K1: Célula | L1: Situação CT-e | M1: Status | N1: Situação Prazo | O1: Categoria | P1: Valor Frete | Q1: Volumes | R1: Modal | S1: Origem | T1: Rt. Entrega | U1: Busca | V1: Passa filtro | X1: ⚠ Aba de tratamento (fórmulas). Não digite nada aqui.
A2: =IFERROR(__xludf.DUMMYFUNCTION("IFERROR(FILTER(ARRAYFORMULA(IFERROR(IF(ISNUMBER(BASE!$K$2:$K$5001),INT(BASE!$K$2:$K$5001),DATEVALUE(BASE!$K$2:$K$5001)),"""")),BASE!$J$2:$J$5001<>""""),"""")"),46304.0) -> 46304 | B2: =IFERROR(__xludf.DUMMYFUNCTION("IFERROR(FILTER(ARRAYFORMULA(IFERROR(IF(ISNUMBER(BASE!$L$2:$L$5001),INT(BASE!$L$2:$L$5001),DATEVALUE(BASE!$L$2:$L$5001)),"""")),BASE!$J$2:$J$5001<>""""),"""")"),46314.0) -> 46314 | C2: =IFERROR(__xludf.DUMMYFUNCTION("IFERROR(FILTER(ARRAYFORMULA(IF(BASE!$O$2:$O$5001="""","""",IFERROR(VALUE(BASE!$O$2:$O$5001),""""))),BASE!$J$2:$J$5001<>""""),"""")"),5.0) -> 5 | D2: =IFERROR(__xludf.DUMMYFUNCTION("IFERROR(FILTER(ARRAYFORMULA(TRIM(BASE!$H$2:$H$5001&"""")),BASE!$J$2:$J$5001<>""""),"""")"),"ITN") -> ITN | E2: =IFERROR(__xludf.DUMMYFUNCTION("IFERROR(FILTER(ARRAYFORMULA(TRIM(BASE!$Y$2:$Y$5001&"""")),BASE!$J$2:$J$5001<>""""),"""")"),"JAM E JÚ CINQUENTENARIO") -> JAM E JÚ CINQUENTENARIO | F2: =IFERROR(__xludf.DUMMYFUNCTION("IFERROR(FILTER(ARRAYFORMULA(TRIM(BASE!$X$2:$X$5001&"""")),BASE!$J$2:$J$5001<>""""),"""")"),"TRIFIL") -> TRIFIL | G2: =IFERROR(__xludf.DUMMYFUNCTION("IFERROR(FILTER(ARRAYFORMULA(TRIM(BASE!$J$2:$J$5001&"""")),BASE!$J$2:$J$5001<>""""),"""")"),"266801541") -> 266801541 | H2: =IFERROR(__xludf.DUMMYFUNCTION("IFERROR(FILTER(ARRAYFORMULA(REGEXREPLACE(TRIM(BASE!$AA$2:$AA$5001&""""),""[,;\s]+$"","""")),BASE!$J$2:$J$5001<>""""),"""")"),"1302858") -> 1302858 | I2: =IFERROR(__xludf.DUMMYFUNCTION("IFERROR(FILTER(ARRAYFORMULA(TRIM(BASE!$I$2:$I$5001&"""")),BASE!$J$2:$J$5001<>""""),"""")"),"946") -> 946 | J2: =IFERROR(__xludf.DUMMYFUNCTION("IFERROR(FILTER(ARRAYFORMULA(TRIM(BASE!$S$2:$S$5001&"""")),BASE!$J$2:$J$5001<>""""),"""")"),"CIF") -> CIF | K2: =IFERROR(__xludf.DUMMYFUNCTION("IFERROR(FILTER(ARRAYFORMULA(IF(BASE!$R$2:$R$5001="""",""(sem célula)"",TRIM(BASE!$R$2:$R$5001&""""))),BASE!$J$2:$J$5001<>""""),"""")"),"(sem célula)") -> (sem célula) | L2: =IFERROR(__xludf.DUMMYFUNCTION("IFERROR(FILTER(ARRAYFORMULA(IF(BASE!$E$2:$E$5001<>"""",UPPER(TRIM(BASE!$E$2:$E$5001&"""")),IF(BASE!$D$2:$D$5001=""N"",""SEM CT-E"",""SEM RETORNO""))),BASE!$J$2:$J$5001<>""""),"""")"),"SEM CT-E") -> SEM CT-E | M2: =IFERROR(__xludf.DUMMYFUNCTION("IFERROR(FILTER(ARRAYFORMULA(TRIM(BASE!$C$2:$C$5001&"""")),BASE!$J$2:$J$5001<>""""),"""")"),"NA ORIGEM") -> NA ORIGEM | N2: =IFERROR(__xludf.DUMMYFUNCTION("IFERROR(FILTER(ARRAYFORMULA(TRIM(BASE!$F$2:$F$5001&"""")),BASE!$J$2:$J$5001<>""""),"""")"),"Antes Prazo") -> Antes Prazo | O2: =IFERROR(__xludf.DUMMYFUNCTION("IFERROR(FILTER(ARRAYFORMULA(IF(BASE!$AC$2:$AC$5001="""",""(não informada)"",TRIM(BASE!$AC$2:$AC$5001&""""))),BASE!$J$2:$J$5001<>""""),"""")"),"B2B") -> B2B | P2: =IFERROR(__xludf.DUMMYFUNCTION("IFERROR(FILTER(ARRAYFORMULA(IF(BASE!$V$2:$V$5001="""",0,IFERROR(VALUE(BASE!$V$2:$V$5001),0))),BASE!$J$2:$J$5001<>""""),"""")"),34.87) -> 34.87 | Q2: =IFERROR(__xludf.DUMMYFUNCTION("IFERROR(FILTER(ARRAYFORMULA(IF(BASE!$W$2:$W$5001="""",0,IFERROR(VALUE(BASE!$W$2:$W$5001),0))),BASE!$J$2:$J$5001<>""""),"""")"),3.0) -> 3 | R2: =IFERROR(__xludf.DUMMYFUNCTION("IFERROR(FILTER(ARRAYFORMULA(TRIM(BASE!$A$2:$A$5001&"""")),BASE!$J$2:$J$5001<>""""),"""")"),"RODO") -> RODO | S2: =IFERROR(__xludf.DUMMYFUNCTION("IFERROR(FILTER(ARRAYFORMULA(TRIM(BASE!$G$2:$G$5001&"""")),BASE!$J$2:$J$5001<>""""),"""")"),"ITN") -> ITN | T2: =IFERROR(__xludf.DUMMYFUNCTION("IFERROR(FILTER(ARRAYFORMULA(TRIM(BASE!$N$2:$N$5001&"""")),BASE!$J$2:$J$5001<>""""),"""")"),"1") -> 1 | U2: =IFERROR(__xludf.DUMMYFUNCTION("IFERROR(FILTER(ARRAYFORMULA(LOWER($G$2:$G$5001&"" ""&$H$2:$H$5001&"" ""&$I$2:$I$5001&"" ""&$E$2:$E$5001&"" ""&$F$2:$F$5001&"" ""&$D$2:$D$5001&"" ""&$T$2:$T$5001)),$G$2:$G$5001<>""""),"""")"),"266801541 1302858 946 jam e jú cinquentenario trifil itn 1") -> 266801541 1302858 946 jam e jú cinquentenario trifil itn 1 | V2: =IFERROR(__xludf.DUMMYFUNCTION("IFERROR(FILTER(ARRAYFORMULA((((((DASH!$B$4="""")*(DASH!$C$4=""""))+(($A$2:$A$5001>=N(DASH!$B$4))*($A$2:$A$5001<=IF(DASH!$C$4="""",99999,DASH!$C$4))))>0)*((((DASH!$D$4="""")*(DASH!$E$4=""""))+(($C$2:$C$5001>=N(DASH!$D$4))*($C$2:$C$5001<=IF(DASH!$E$4="""",9"&"9999,DASH!$E$4))))>0)*(((DASH!$F$4="""")+(DASH!$F$4=""Todos"")+($D$2:$D$5001=DASH!$F$4))>0)*(((DASH!$G$4="""")+(DASH!$G$4=""Todos"")+($F$2:$F$5001=DASH!$G$4))>0)*(((DASH!$H$4="""")+(DASH!$H$4=""Todos"")+($L$2:$L$5001=DASH!$H$4))>0)*(((DASH!$I$4="""")+(DAS"&"H!$I$4=""Todos"")+($J$2:$J$5001=DASH!$I$4))>0)*(((DASH!$J$4="""")+(DASH!$J$4=""Todos"")+($K$2:$K$5001=DASH!$J$4))>0)*(((DASH!$K$4="""")+(DASH!$K$4=""Todos"")+($O$2:$O$5001=DASH!$K$4))>0)*(((DASH!$L$4="""")+ISNUMBER(SEARCH(LOWER(DASH!$L$4&""""),$U$2:$U$500"&"1)))>0))=1),$G$2:$G$5001<>""""),"""")"),FALSE) -> FALSE
A3: =IFERROR(__xludf.DUMMYFUNCTION("""COMPUTED_VALUE"""),46304.0) -> 46304 | B3: =IFERROR(__xludf.DUMMYFUNCTION("""COMPUTED_VALUE"""),46316.0) -> 46316 | C3: =IFERROR(__xludf.DUMMYFUNCTION("""COMPUTED_VALUE"""),7.0) -> 7 | D3: =IFERROR(__xludf.DUMMYFUNCTION("""COMPUTED_VALUE"""),"SAO") -> SAO | E3: =IFERROR(__xludf.DUMMYFUNCTION("""COMPUTED_VALUE"""),"ACHE LABORATORIOS FARMACEUTICOS SA") -> ACHE LABORATORIOS FARMACEUTICOS SA | F3: =IFERROR(__xludf.DUMMYFUNCTION("""COMPUTED_VALUE"""),"TRIFIL") -> TRIFIL | G3: =IFERROR(__xludf.DUMMYFUNCTION("""COMPUTED_VALUE"""),"266801850") -> 266801850 | H3: =IFERROR(__xludf.DUMMYFUNCTION("""COMPUTED_VALUE"""),"70000284") -> 70000284 | I3: =IFERROR(__xludf.DUMMYFUNCTION("""COMPUTED_VALUE"""),"8176609") -> 8176609 | J3: =IFERROR(__xludf.DUMMYFUNCTION("""COMPUTED_VALUE"""),"CSG") -> CSG | K3: =IFERROR(__xludf.DUMMYFUNCTION("""COMPUTED_VALUE"""),"SAO-1") -> SAO-1 | L3: =IFERROR(__xludf.DUMMYFUNCTION("""COMPUTED_VALUE"""),"SEM CT-E") -> SEM CT-E | M3: =IFERROR(__xludf.DUMMYFUNCTION("""COMPUTED_VALUE"""),"NA ORIGEM") -> NA ORIGEM | N3: =IFERROR(__xludf.DUMMYFUNCTION("""COMPUTED_VALUE"""),"Antes Prazo") -> Antes Prazo | O3: =IFERROR(__xludf.DUMMYFUNCTION("""COMPUTED_VALUE"""),"(não informada)") -> (não informada) | P3: =IFERROR(__xludf.DUMMYFUNCTION("""COMPUTED_VALUE"""),1.0) -> 1 | Q3: =IFERROR(__xludf.DUMMYFUNCTION("""COMPUTED_VALUE"""),1.0) -> 1 | R3: =IFERROR(__xludf.DUMMYFUNCTION("""COMPUTED_VALUE"""),"RODO") -> RODO | S3: =IFERROR(__xludf.DUMMYFUNCTION("""COMPUTED_VALUE"""),"ITN") -> ITN | T3: =IFERROR(__xludf.DUMMYFUNCTION("""COMPUTED_VALUE"""),"34") -> 34 | U3: =IFERROR(__xludf.DUMMYFUNCTION("""COMPUTED_VALUE"""),"266801850 70000284 8176609 ache laboratorios farmaceuticos sa trifil sao 34") -> 266801850 70000284 8176609 ache laboratorios farmaceuticos sa trifil sao 34 | V3: =IFERROR(__xludf.DUMMYFUNCTION("""COMPUTED_VALUE"""),FALSE) -> FALSE
A4: =IFERROR(__xludf.DUMMYFUNCTION("""COMPUTED_VALUE"""),46304.0) -> 46304 | B4: =IFERROR(__xludf.DUMMYFUNCTION("""COMPUTED_VALUE"""),46317.0) -> 46317 | C4: =IFERROR(__xludf.DUMMYFUNCTION("""COMPUTED_VALUE"""),8.0) -> 8 | D4: =IFERROR(__xludf.DUMMYFUNCTION("""COMPUTED_VALUE"""),"ATB") -> ATB | E4: =IFERROR(__xludf.DUMMYFUNCTION("""COMPUTED_VALUE"""),"LOJAS EDLOPES") -> LOJAS EDLOPES | F4: =IFERROR(__xludf.DUMMYFUNCTION("""COMPUTED_VALUE"""),"TRIFIL") -> TRIFIL | G4: =IFERROR(__xludf.DUMMYFUNCTION("""COMPUTED_VALUE"""),"266802183") -> 266802183 | H4: =IFERROR(__xludf.DUMMYFUNCTION("""COMPUTED_VALUE"""),"1306031") -> 1306031 | I4: =IFERROR(__xludf.DUMMYFUNCTION("""COMPUTED_VALUE"""),"8177101") -> 8177101 | J4: =IFERROR(__xludf.DUMMYFUNCTION("""COMPUTED_VALUE"""),"CIF") -> CIF | K4: =IFERROR(__xludf.DUMMYFUNCTION("""COMPUTED_VALUE"""),"SAO-1") -> SAO-1 | L4: =IFERROR(__xludf.DUMMYFUNCTION("""COMPUTED_VALUE"""),"AUTORIZADO") -> AUTORIZADO | M4: =IFERROR(__xludf.DUMMYFUNCTION("""COMPUTED_VALUE"""),"NA ORIGEM") -> NA ORIGEM | N4: =IFERROR(__xludf.DUMMYFUNCTION("""COMPUTED_VALUE"""),"Antes Prazo") -> Antes Prazo | O4: =IFERROR(__xludf.DUMMYFUNCTION("""COMPUTED_VALUE"""),"B2B") -> B2B | P4: =IFERROR(__xludf.DUMMYFUNCTION("""COMPUTED_VALUE"""),38.46) -> 38.46 | Q4: =IFERROR(__xludf.DUMMYFUNCTION("""COMPUTED_VALUE"""),3.0) -> 3 | R4: =IFERROR(__xludf.DUMMYFUNCTION("""COMPUTED_VALUE"""),"RODO") -> RODO | S4: =IFERROR(__xludf.DUMMYFUNCTION("""COMPUTED_VALUE"""),"ITN") -> ITN | T4: =IFERROR(__xludf.DUMMYFUNCTION("""COMPUTED_VALUE"""),"103") -> 103 | U4: =IFERROR(__xludf.DUMMYFUNCTION("""COMPUTED_VALUE"""),"266802183 1306031 8177101 lojas edlopes trifil atb 103") -> 266802183 1306031 8177101 lojas edlopes trifil atb 103 | V4: =IFERROR(__xludf.DUMMYFUNCTION("""COMPUTED_VALUE"""),FALSE) -> FALSE
A5: =IFERROR(__xludf.DUMMYFUNCTION("""COMPUTED_VALUE"""),46304.0) -> 46304 | B5: =IFERROR(__xludf.DUMMYFUNCTION("""COMPUTED_VALUE"""),46317.0) -> 46317 | C5: =IFERROR(__xludf.DUMMYFUNCTION("""COMPUTED_VALUE"""),8.0) -> 8 | D5: =IFERROR(__xludf.DUMMYFUNCTION("""COMPUTED_VALUE"""),"MMG") -> MMG | E5: =IFERROR(__xludf.DUMMYFUNCTION("""COMPUTED_VALUE"""),"BELLAS MEIAS E LINGERIES LTDA") -> BELLAS MEIAS E LINGERIES LTDA | F5: =IFERROR(__xludf.DUMMYFUNCTION("""COMPUTED_VALUE"""),"TRIFIL") -> TRIFIL | G5: =IFERROR(__xludf.DUMMYFUNCTION("""COMPUTED_VALUE"""),"266802184") -> 266802184 | H5: =IFERROR(__xludf.DUMMYFUNCTION("""COMPUTED_VALUE"""),"1305597") -> 1305597 | I5: =IFERROR(__xludf.DUMMYFUNCTION("""COMPUTED_VALUE"""),"8177082") -> 8177082 | J5: =IFERROR(__xludf.DUMMYFUNCTION("""COMPUTED_VALUE"""),"CIF") -> CIF | K5: =IFERROR(__xludf.DUMMYFUNCTION("""COMPUTED_VALUE"""),"SAO-1") -> SAO-1 | L5: =IFERROR(__xludf.DUMMYFUNCTION("""COMPUTED_VALUE"""),"AUTORIZADO") -> AUTORIZADO | M5: =IFERROR(__xludf.DUMMYFUNCTION("""COMPUTED_VALUE"""),"NA ORIGEM") -> NA ORIGEM | N5: =IFERROR(__xludf.DUMMYFUNCTION("""COMPUTED_VALUE"""),"Antes Prazo") -> Antes Prazo | O5: =IFERROR(__xludf.DUMMYFUNCTION("""COMPUTED_VALUE"""),"B2B") -> B2B | P5: =IFERROR(__xludf.DUMMYFUNCTION("""COMPUTED_VALUE"""),38.46) -> 38.46 | Q5: =IFERROR(__xludf.DUMMYFUNCTION("""COMPUTED_VALUE"""),2.0) -> 2 | R5: =IFERROR(__xludf.DUMMYFUNCTION("""COMPUTED_VALUE"""),"RODO") -> RODO | S5: =IFERROR(__xludf.DUMMYFUNCTION("""COMPUTED_VALUE"""),"ITN") -> ITN | T5: =IFERROR(__xludf.DUMMYFUNCTION("""COMPUTED_VALUE"""),"40") -> 40 | U5: =IFERROR(__xludf.DUMMYFUNCTION("""COMPUTED_VALUE"""),"266802184 1305597 8177082 bellas meias e lingeries ltda trifil mmg 40") -> 266802184 1305597 8177082 bellas meias e lingeries ltda trifil mmg 40 | V5: =IFERROR(__xludf.DUMMYFUNCTION("""COMPUTED_VALUE"""),FALSE) -> FALSE
A6: =IFERROR(__xludf.DUMMYFUNCTION("""COMPUTED_VALUE"""),46304.0) -> 46304 | B6: =IFERROR(__xludf.DUMMYFUNCTION("""COMPUTED_VALUE"""),46317.0) -> 46317 | C6: =IFERROR(__xludf.DUMMYFUNCTION("""COMPUTED_VALUE"""),8.0) -> 8 | D6: =IFERROR(__xludf.DUMMYFUNCTION("""COMPUTED_VALUE"""),"SJP") -> SJP | E6: =IFERROR(__xludf.DUMMYFUNCTION("""COMPUTED_VALUE"""),"VIVIANE REBECA DE FREITAS FIRME") -> VIVIANE REBECA DE FREITAS FIRME | F6: =IFERROR(__xludf.DUMMYFUNCTION("""COMPUTED_VALUE"""),"TRIFIL") -> TRIFIL | G6: =IFERROR(__xludf.DUMMYFUNCTION("""COMPUTED_VALUE"""),"266802185") -> 266802185 | H6: =IFERROR(__xludf.DUMMYFUNCTION("""COMPUTED_VALUE"""),"1306021") -> 1306021 | I6: =IFERROR(__xludf.DUMMYFUNCTION("""COMPUTED_VALUE"""),"8177106") -> 8177106 | J6: =IFERROR(__xludf.DUMMYFUNCTION("""COMPUTED_VALUE"""),"CIF") -> CIF | K6: =IFERROR(__xludf.DUMMYFUNCTION("""COMPUTED_VALUE"""),"SAO-1") -> SAO-1 | L6: =IFERROR(__xludf.DUMMYFUNCTION("""COMPUTED_VALUE"""),"AUTORIZADO") -> AUTORIZADO | M6: =IFERROR(__xludf.DUMMYFUNCTION("""COMPUTED_VALUE"""),"NA ORIGEM") -> NA ORIGEM | N6: =IFERROR(__xludf.DUMMYFUNCTION("""COMPUTED_VALUE"""),"Antes Prazo") -> Antes Prazo | O6: =IFERROR(__xludf.DUMMYFUNCTION("""COMPUTED_VALUE"""),"B2B") -> B2B | P6: =IFERROR(__xludf.DUMMYFUNCTION("""COMPUTED_VALUE"""),136.07) -> 136.07 | Q6: =IFERROR(__xludf.DUMMYFUNCTION("""COMPUTED_VALUE"""),37.0) -> 37 | R6: =IFERROR(__xludf.DUMMYFUNCTION("""COMPUTED_VALUE"""),"RODO") -> RODO | S6: =IFERROR(__xludf.DUMMYFUNCTION("""COMPUTED_VALUE"""),"ITN") -> ITN | T6: =IFERROR(__xludf.DUMMYFUNCTION("""COMPUTED_VALUE"""),"101") -> 101 | U6: =IFERROR(__xludf.DUMMYFUNCTION("""COMPUTED_VALUE"""),"266802185 1306021 8177106 viviane rebeca de freitas firme trifil sjp 101") -> 266802185 1306021 8177106 viviane rebeca de freitas firme trifil sjp 101 | V6: =IFERROR(__xludf.DUMMYFUNCTION("""COMPUTED_VALUE"""),FALSE) -> FALSE
A7: =IFERROR(__xludf.DUMMYFUNCTION("""COMPUTED_VALUE"""),46304.0) -> 46304 | B7: =IFERROR(__xludf.DUMMYFUNCTION("""COMPUTED_VALUE"""),46316.0) -> 46316 | C7: =IFERROR(__xludf.DUMMYFUNCTION("""COMPUTED_VALUE"""),7.0) -> 7 | D7: =IFERROR(__xludf.DUMMYFUNCTION("""COMPUTED_VALUE"""),"AQA") -> AQA | E7: =IFERROR(__xludf.DUMMYFUNCTION("""COMPUTED_VALUE"""),"LOJAS LUPO") -> LOJAS LUPO | F7: =IFERROR(__xludf.DUMMYFUNCTION("""COMPUTED_VALUE"""),"TRIFIL") -> TRIFIL | G7: =IFERROR(__xludf.DUMMYFUNCTION("""COMPUTED_VALUE"""),"266802186") -> 266802186 | H7: =IFERROR(__xludf.DUMMYFUNCTION("""COMPUTED_VALUE"""),"1304628") -> 1304628 | I7: =IFERROR(__xludf.DUMMYFUNCTION("""COMPUTED_VALUE"""),"8177107") -> 8177107 | J7: =IFERROR(__xludf.DUMMYFUNCTION("""COMPUTED_VALUE"""),"CIF") -> CIF | K7: =IFERROR(__xludf.DUMMYFUNCTION("""COMPUTED_VALUE"""),"SAO-1") -> SAO-1 | L7: =IFERROR(__xludf.DUMMYFUNCTION("""COMPUTED_VALUE"""),"AUTORIZADO") -> AUTORIZADO | M7: =IFERROR(__xludf.DUMMYFUNCTION("""COMPUTED_VALUE"""),"NA ORIGEM") -> NA ORIGEM | N7: =IFERROR(__xludf.DUMMYFUNCTION("""COMPUTED_VALUE"""),"Antes Prazo") -> Antes Prazo | O7: =IFERROR(__xludf.DUMMYFUNCTION("""COMPUTED_VALUE"""),"B2B") -> B2B | P7: =IFERROR(__xludf.DUMMYFUNCTION("""COMPUTED_VALUE"""),310.68) -> 310.68 | Q7: =IFERROR(__xludf.DUMMYFUNCTION("""COMPUTED_VALUE"""),56.0) -> 56 | R7: =IFERROR(__xludf.DUMMYFUNCTION("""COMPUTED_VALUE"""),"RODO") -> RODO | S7: =IFERROR(__xludf.DUMMYFUNCTION("""COMPUTED_VALUE"""),"ITN") -> ITN | T7: =IFERROR(__xludf.DUMMYFUNCTION("""COMPUTED_VALUE"""),"2") -> 2 | U7: =IFERROR(__xludf.DUMMYFUNCTION("""COMPUTED_VALUE"""),"266802186 1304628 8177107 lojas lupo trifil aqa 2") -> 266802186 1304628 8177107 lojas lupo trifil aqa 2 | V7: =IFERROR(__xludf.DUMMYFUNCTION("""COMPUTED_VALUE"""),FALSE) -> FALSE
A8: =IFERROR(__xludf.DUMMYFUNCTION("""COMPUTED_VALUE"""),46304.0) -> 46304 | B8: =IFERROR(__xludf.DUMMYFUNCTION("""COMPUTED_VALUE"""),46323.0) -> 46323 | C8: =IFERROR(__xludf.DUMMYFUNCTION("""COMPUTED_VALUE"""),12.0) -> 12 | D8: =IFERROR(__xludf.DUMMYFUNCTION("""COMPUTED_VALUE"""),"SOD") -> SOD | E8: =IFERROR(__xludf.DUMMYFUNCTION("""COMPUTED_VALUE"""),"MASTHER VARIEDADES LTDA") -> MASTHER VARIEDADES LTDA | F8: =IFERROR(__xludf.DUMMYFUNCTION("""COMPUTED_VALUE"""),"TRIFIL") -> TRIFIL | G8: =IFERROR(__xludf.DUMMYFUNCTION("""COMPUTED_VALUE"""),"266802187") -> 266802187 | H8: =IFERROR(__xludf.DUMMYFUNCTION("""COMPUTED_VALUE"""),"1305607") -> 1305607 | I8: =IFERROR(__xludf.DUMMYFUNCTION("""COMPUTED_VALUE"""),"8177083") -> 8177083 | J8: =IFERROR(__xludf.DUMMYFUNCTION("""COMPUTED_VALUE"""),"CIF") -> CIF | K8: =IFERROR(__xludf.DUMMYFUNCTION("""COMPUTED_VALUE"""),"SAO-1") -> SAO-1 | L8: =IFERROR(__xludf.DUMMYFUNCTION("""COMPUTED_VALUE"""),"AUTORIZADO") -> AUTORIZADO | M8: =IFERROR(__xludf.DUMMYFUNCTION("""COMPUTED_VALUE"""),"NA ORIGEM") -> NA ORIGEM | N8: =IFERROR(__xludf.DUMMYFUNCTION("""COMPUTED_VALUE"""),"Antes Prazo") -> Antes Prazo | O8: =IFERROR(__xludf.DUMMYFUNCTION("""COMPUTED_VALUE"""),"B2B") -> B2B | P8: =IFERROR(__xludf.DUMMYFUNCTION("""COMPUTED_VALUE"""),38.46) -> 38.46 | Q8: =IFERROR(__xludf.DUMMYFUNCTION("""COMPUTED_VALUE"""),3.0) -> 3 | R8: =IFERROR(__xludf.DUMMYFUNCTION("""COMPUTED_VALUE"""),"RODO") -> RODO | S8: =IFERROR(__xludf.DUMMYFUNCTION("""COMPUTED_VALUE"""),"ITN") -> ITN | T8: =IFERROR(__xludf.DUMMYFUNCTION("""COMPUTED_VALUE"""),"107") -> 107 | U8: =IFERROR(__xludf.DUMMYFUNCTION("""COMPUTED_VALUE"""),"266802187 1305607 8177083 masther variedades ltda trifil sod 107") -> 266802187 1305607 8177083 masther variedades ltda trifil sod 107 | V8: =IFERROR(__xludf.DUMMYFUNCTION("""COMPUTED_VALUE"""),FALSE) -> FALSE
A9: =IFERROR(__xludf.DUMMYFUNCTION("""COMPUTED_VALUE"""),46304.0) -> 46304 | B9: =IFERROR(__xludf.DUMMYFUNCTION("""COMPUTED_VALUE"""),46317.0) -> 46317 | C9: =IFERROR(__xludf.DUMMYFUNCTION("""COMPUTED_VALUE"""),8.0) -> 8 | D9: =IFERROR(__xludf.DUMMYFUNCTION("""COMPUTED_VALUE"""),"SOD") -> SOD | E9: =IFERROR(__xludf.DUMMYFUNCTION("""COMPUTED_VALUE"""),"MILENE PEDROSO FAVARO ME") -> MILENE PEDROSO FAVARO ME | F9: =IFERROR(__xludf.DUMMYFUNCTION("""COMPUTED_VALUE"""),"TRIFIL") -> TRIFIL | G9: =IFERROR(__xludf.DUMMYFUNCTION("""COMPUTED_VALUE"""),"266802188") -> 266802188 | H9: =IFERROR(__xludf.DUMMYFUNCTION("""COMPUTED_VALUE"""),"1305858") -> 1305858 | I9: =IFERROR(__xludf.DUMMYFUNCTION("""COMPUTED_VALUE"""),"8177084") -> 8177084 | J9: =IFERROR(__xludf.DUMMYFUNCTION("""COMPUTED_VALUE"""),"CIF") -> CIF | K9: =IFERROR(__xludf.DUMMYFUNCTION("""COMPUTED_VALUE"""),"SAO-1") -> SAO-1 | L9: =IFERROR(__xludf.DUMMYFUNCTION("""COMPUTED_VALUE"""),"AUTORIZADO") -> AUTORIZADO | M9: =IFERROR(__xludf.DUMMYFUNCTION("""COMPUTED_VALUE"""),"NA ORIGEM") -> NA ORIGEM | N9: =IFERROR(__xludf.DUMMYFUNCTION("""COMPUTED_VALUE"""),"Antes Prazo") -> Antes Prazo | O9: =IFERROR(__xludf.DUMMYFUNCTION("""COMPUTED_VALUE"""),"B2B") -> B2B | P9: =IFERROR(__xludf.DUMMYFUNCTION("""COMPUTED_VALUE"""),38.46) -> 38.46 | Q9: =IFERROR(__xludf.DUMMYFUNCTION("""COMPUTED_VALUE"""),2.0) -> 2 | R9: =IFERROR(__xludf.DUMMYFUNCTION("""COMPUTED_VALUE"""),"RODO") -> RODO | S9: =IFERROR(__xludf.DUMMYFUNCTION("""COMPUTED_VALUE"""),"ITN") -> ITN | T9: =IFERROR(__xludf.DUMMYFUNCTION("""COMPUTED_VALUE"""),"104") -> 104 | U9: =IFERROR(__xludf.DUMMYFUNCTION("""COMPUTED_VALUE"""),"266802188 1305858 8177084 milene pedroso favaro me trifil sod 104") -> 266802188 1305858 8177084 milene pedroso favaro me trifil sod 104 | V9: =IFERROR(__xludf.DUMMYFUNCTION("""COMPUTED_VALUE"""),FALSE) -> FALSE
A10: =IFERROR(__xludf.DUMMYFUNCTION("""COMPUTED_VALUE"""),46304.0) -> 46304 | B10: =IFERROR(__xludf.DUMMYFUNCTION("""COMPUTED_VALUE"""),46316.0) -> 46316 | C10: =IFERROR(__xludf.DUMMYFUNCTION("""COMPUTED_VALUE"""),7.0) -> 7 | D10: =IFERROR(__xludf.DUMMYFUNCTION("""COMPUTED_VALUE"""),"RIO") -> RIO | E10: =IFERROR(__xludf.DUMMYFUNCTION("""COMPUTED_VALUE"""),"H. V. MODAS LTDA - ME") -> H. V. MODAS LTDA - ME | F10: =IFERROR(__xludf.DUMMYFUNCTION("""COMPUTED_VALUE"""),"TRIFIL") -> TRIFIL | G10: =IFERROR(__xludf.DUMMYFUNCTION("""COMPUTED_VALUE"""),"266802189") -> 266802189 | H10: =IFERROR(__xludf.DUMMYFUNCTION("""COMPUTED_VALUE"""),"1305850") -> 1305850 | I10: =IFERROR(__xludf.DUMMYFUNCTION("""COMPUTED_VALUE"""),"8177078") -> 8177078 | J10: =IFERROR(__xludf.DUMMYFUNCTION("""COMPUTED_VALUE"""),"CIF") -> CIF | K10: =IFERROR(__xludf.DUMMYFUNCTION("""COMPUTED_VALUE"""),"(sem célula)") -> (sem célula) | L10: =IFERROR(__xludf.DUMMYFUNCTION("""COMPUTED_VALUE"""),"AUTORIZADO") -> AUTORIZADO | M10: =IFERROR(__xludf.DUMMYFUNCTION("""COMPUTED_VALUE"""),"NA ORIGEM") -> NA ORIGEM | N10: =IFERROR(__xludf.DUMMYFUNCTION("""COMPUTED_VALUE"""),"Antes Prazo") -> Antes Prazo | O10: =IFERROR(__xludf.DUMMYFUNCTION("""COMPUTED_VALUE"""),"B2B") -> B2B | P10: =IFERROR(__xludf.DUMMYFUNCTION("""COMPUTED_VALUE"""),69.49) -> 69.49 | Q10: =IFERROR(__xludf.DUMMYFUNCTION("""COMPUTED_VALUE"""),1.0) -> 1 | R10: =IFERROR(__xludf.DUMMYFUNCTION("""COMPUTED_VALUE"""),"RODO") -> RODO | S10: =IFERROR(__xludf.DUMMYFUNCTION("""COMPUTED_VALUE"""),"ITN") -> ITN | T10: =IFERROR(__xludf.DUMMYFUNCTION("""COMPUTED_VALUE"""),"62") -> 62 | U10: =IFERROR(__xludf.DUMMYFUNCTION("""COMPUTED_VALUE"""),"266802189 1305850 8177078 h. v. modas ltda - me trifil rio 62") -> 266802189 1305850 8177078 h. v. modas ltda - me trifil rio 62 | V10: =IFERROR(__xludf.DUMMYFUNCTION("""COMPUTED_VALUE"""),FALSE) -> FALSE
A11: =IFERROR(__xludf.DUMMYFUNCTION("""COMPUTED_VALUE"""),46304.0) -> 46304 | B11: =IFERROR(__xludf.DUMMYFUNCTION("""COMPUTED_VALUE"""),46316.0) -> 46316 | C11: =IFERROR(__xludf.DUMMYFUNCTION("""COMPUTED_VALUE"""),7.0) -> 7 | D11: =IFERROR(__xludf.DUMMYFUNCTION("""COMPUTED_VALUE"""),"BHZ") -> BHZ | E11: =IFERROR(__xludf.DUMMYFUNCTION("""COMPUTED_VALUE"""),"LUPO") -> LUPO | F11: =IFERROR(__xludf.DUMMYFUNCTION("""COMPUTED_VALUE"""),"TRIFIL") -> TRIFIL | G11: =IFERROR(__xludf.DUMMYFUNCTION("""COMPUTED_VALUE"""),"266802190") -> 266802190 | H11: =IFERROR(__xludf.DUMMYFUNCTION("""COMPUTED_VALUE"""),"1305803") -> 1305803 | I11: =IFERROR(__xludf.DUMMYFUNCTION("""COMPUTED_VALUE"""),"8177085") -> 8177085 | J11: =IFERROR(__xludf.DUMMYFUNCTION("""COMPUTED_VALUE"""),"CIF") -> CIF | K11: =IFERROR(__xludf.DUMMYFUNCTION("""COMPUTED_VALUE"""),"(sem célula)") -> (sem célula) | L11: =IFERROR(__xludf.DUMMYFUNCTION("""COMPUTED_VALUE"""),"AUTORIZADO") -> AUTORIZADO | M11: =IFERROR(__xludf.DUMMYFUNCTION("""COMPUTED_VALUE"""),"NA ORIGEM") -> NA ORIGEM | N11: =IFERROR(__xludf.DUMMYFUNCTION("""COMPUTED_VALUE"""),"Antes Prazo") -> Antes Prazo | O11: =IFERROR(__xludf.DUMMYFUNCTION("""COMPUTED_VALUE"""),"B2B") -> B2B | P11: =IFERROR(__xludf.DUMMYFUNCTION("""COMPUTED_VALUE"""),66.52) -> 66.52 | Q11: =IFERROR(__xludf.DUMMYFUNCTION("""COMPUTED_VALUE"""),7.0) -> 7 | R11: =IFERROR(__xludf.DUMMYFUNCTION("""COMPUTED_VALUE"""),"RODO") -> RODO | S11: =IFERROR(__xludf.DUMMYFUNCTION("""COMPUTED_VALUE"""),"ITN") -> ITN | T11: =IFERROR(__xludf.DUMMYFUNCTION("""COMPUTED_VALUE"""),"2") -> 2 | U11: =IFERROR(__xludf.DUMMYFUNCTION("""COMPUTED_VALUE"""),"266802190 1305803 8177085 lupo trifil bhz 2") -> 266802190 1305803 8177085 lupo trifil bhz 2 | V11: =IFERROR(__xludf.DUMMYFUNCTION("""COMPUTED_VALUE"""),FALSE) -> FALSE
